Traceback (most recent call last):
  File "/media/siothrun/Backup/Thesis/my_code/pytorch-biggraph-gpu/bin/torchbiggraph_eval", line 11, in <module>
    load_entry_point('torchbiggraph==1.0.1.dev0', 'console_scripts', 'torchbiggraph_eval')()
  File "/media/siothrun/Backup/Thesis/my_code/pytorch-biggraph-gpu/lib/python3.8/site-packages/torchbiggraph/eval.py", line 262, in main
    do_eval(config, subprocess_init=subprocess_init)
  File "/media/siothrun/Backup/Thesis/my_code/pytorch-biggraph-gpu/lib/python3.8/site-packages/torchbiggraph/eval.py", line 239, in do_eval
    for _ in do_eval_and_report_stats(config, model, evaluator, subprocess_init):
  File "/media/siothrun/Backup/Thesis/my_code/pytorch-biggraph-gpu/lib/python3.8/site-packages/torchbiggraph/eval.py", line 163, in do_eval_and_report_stats
    embs = load_embeddings(entity, part)
  File "/media/siothrun/Backup/Thesis/my_code/pytorch-biggraph-gpu/lib/python3.8/site-packages/torchbiggraph/eval.py", line 114, in load_embeddings
    embs, _ = checkpoint_manager.read(entity, part)
  File "/media/siothrun/Backup/Thesis/my_code/pytorch-biggraph-gpu/lib/python3.8/site-packages/torchbiggraph/checkpoint_manager.py", line 297, in read
    embs, serialized_optim_state = self.storage.load_entity_partition(
  File "/media/siothrun/Backup/Thesis/my_code/pytorch-biggraph-gpu/lib/python3.8/site-packages/torchbiggraph/checkpoint_storage.py", line 351, in load_entity_partition
    raise err
  File "/media/siothrun/Backup/Thesis/my_code/pytorch-biggraph-gpu/lib/python3.8/site-packages/torchbiggraph/checkpoint_storage.py", line 344, in load_entity_partition
    embs = load_embeddings(hf, out=out)
  File "/media/siothrun/Backup/Thesis/my_code/pytorch-biggraph-gpu/lib/python3.8/site-packages/torchbiggraph/checkpoint_storage.py", line 168, in load_embeddings
    dataset.read_direct(out.numpy())
  File "/media/siothrun/Backup/Thesis/my_code/pytorch-biggraph-gpu/lib/python3.8/site-packages/h5py/_hl/dataset.py", line 973, in read_direct
    self.id.read(mspace, fspace, dest, dxpl=self._dxpl)
  File "h5py/_objects.pyx", line 54, in h5py._objects.with_phil.wrapper
  File "h5py/_objects.pyx", line 55, in h5py._objects.with_phil.wrapper
  File "h5py/h5d.pyx", line 192, in h5py.h5d.DatasetID.read
  File "h5py/_proxy.pyx", line 112, in h5py._proxy.dset_rw
OSError: [Errno 14] Can't read data (file read failed: time = Sat Jun 26 12:43:33 2021
, filename = '/media/siothrun/Backup/Thesis/my_code/backup_points/bioportal_final/embeddings_all_2.v50.h5', file descriptor = 32, errno = 14, error message = 'Bad address', buf = 0x7f1496ee7000, total read size = 1110525376, bytes this sub-read = 1110525376, bytes actually read = 18446744073709551615, offset = 0)
